[2025-03-08T08:03:33.460+0000] {local_task_job_runner.py:120} INFO - ::group::Pre task execution logs
[2025-03-08T08:03:33.485+0000] {taskinstance.py:2076} INFO - Dependencies all met for dep_context=non-requeueable deps ti=<TaskInstance: submit_spark_job_v2.submit_spark_via_ssh scheduled__2025-03-07T00:00:00+00:00 [queued]>
[2025-03-08T08:03:33.495+0000] {taskinstance.py:2076} INFO - Dependencies all met for dep_context=requeueable deps ti=<TaskInstance: submit_spark_job_v2.submit_spark_via_ssh scheduled__2025-03-07T00:00:00+00:00 [queued]>
[2025-03-08T08:03:33.496+0000] {taskinstance.py:2306} INFO - Starting attempt 2 of 3
[2025-03-08T08:03:33.510+0000] {taskinstance.py:2330} INFO - Executing <Task(SSHOperator): submit_spark_via_ssh> on 2025-03-07 00:00:00+00:00
[2025-03-08T08:03:33.515+0000] {standard_task_runner.py:63} INFO - Started process 10937 to run task
[2025-03-08T08:03:33.519+0000] {standard_task_runner.py:90} INFO - Running: ['***', 'tasks', 'run', 'submit_spark_job_v2', 'submit_spark_via_ssh', 'scheduled__2025-03-07T00:00:00+00:00', '--job-id', '33', '--raw', '--subdir', 'DAGS_FOLDER/match_info_spark_process_v2.py', '--cfg-path', '/tmp/tmpt8tziwyw']
[2025-03-08T08:03:33.521+0000] {standard_task_runner.py:91} INFO - Job 33: Subtask submit_spark_via_ssh
[2025-03-08T08:03:33.590+0000] {task_command.py:426} INFO - Running <TaskInstance: submit_spark_job_v2.submit_spark_via_ssh scheduled__2025-03-07T00:00:00+00:00 [running]> on host be828dc9717c
[2025-03-08T08:03:33.703+0000] {taskinstance.py:2648} INFO - Exporting env vars: AIRFLOW_CTX_DAG_OWNER='***' AIRFLOW_CTX_DAG_ID='submit_spark_job_v2' AIRFLOW_CTX_TASK_ID='submit_spark_via_ssh' AIRFLOW_CTX_EXECUTION_DATE='2025-03-07T00:00:00+00:00' AIRFLOW_CTX_TRY_NUMBER='2' AIRFLOW_CTX_DAG_RUN_ID='scheduled__2025-03-07T00:00:00+00:00'
[2025-03-08T08:03:33.704+0000] {taskinstance.py:430} INFO - ::endgroup::
[2025-03-08T08:03:33.720+0000] {ssh.py:151} INFO - Creating ssh_client
[2025-03-08T08:03:33.720+0000] {ssh.py:124} INFO - ssh_hook is not provided or invalid. Trying ssh_conn_id to create SSHHook.
[2025-03-08T08:03:33.734+0000] {base.py:84} INFO - Using connection ID 'spark_ssh_conn' for task execution.
[2025-03-08T08:03:33.737+0000] {ssh.py:301} WARNING - No Host Key Verification. This won't protect against Man-In-The-Middle attacks
[2025-03-08T08:03:33.741+0000] {ssh.py:343} INFO - Failed to connect. Sleeping before retry attempt 1
[2025-03-08T08:03:37.396+0000] {ssh.py:343} INFO - Failed to connect. Sleeping before retry attempt 2
[2025-03-08T08:03:40.860+0000] {taskinstance.py:441} INFO - ::group::Post task execution logs
[2025-03-08T08:03:40.861+0000] {taskinstance.py:2905} ERROR - Task failed with exception
Traceback (most recent call last):
  File "/home/airflow/.local/lib/python3.9/site-packages/airflow/models/taskinstance.py", line 465, in _execute_task
    result = _execute_callable(context=context, **execute_callable_kwargs)
  File "/home/airflow/.local/lib/python3.9/site-packages/airflow/models/taskinstance.py", line 432, in _execute_callable
    return execute_callable(context=context, **execute_callable_kwargs)
  File "/home/airflow/.local/lib/python3.9/site-packages/airflow/models/baseoperator.py", line 400, in wrapper
    return func(self, *args, **kwargs)
  File "/home/airflow/.local/lib/python3.9/site-packages/airflow/providers/ssh/operators/ssh.py", line 190, in execute
    with self.get_ssh_client() as ssh_client:
  File "/home/airflow/.local/lib/python3.9/site-packages/airflow/providers/ssh/operators/ssh.py", line 152, in get_ssh_client
    return self.hook.get_conn()
  File "/home/airflow/.local/lib/python3.9/site-packages/airflow/providers/ssh/hooks/ssh.py", line 347, in get_conn
    for attempt in Retrying(
  File "/home/airflow/.local/lib/python3.9/site-packages/tenacity/__init__.py", line 347, in __iter__
    do = self.iter(retry_state=retry_state)
  File "/home/airflow/.local/lib/python3.9/site-packages/tenacity/__init__.py", line 325, in iter
    raise retry_exc.reraise()
  File "/home/airflow/.local/lib/python3.9/site-packages/tenacity/__init__.py", line 158, in reraise
    raise self.last_attempt.result()
  File "/usr/local/lib/python3.9/concurrent/futures/_base.py", line 439, in result
    return self.__get_result()
  File "/usr/local/lib/python3.9/concurrent/futures/_base.py", line 391, in __get_result
    raise self._exception
  File "/home/airflow/.local/lib/python3.9/site-packages/airflow/providers/ssh/hooks/ssh.py", line 354, in get_conn
    client.connect(**connect_kwargs)
  File "/home/airflow/.local/lib/python3.9/site-packages/paramiko/client.py", line 409, in connect
    raise NoValidConnectionsError(errors)
paramiko.ssh_exception.NoValidConnectionsError: [Errno None] Unable to connect to port 777 on 172.31.12.182
[2025-03-08T08:03:40.877+0000] {taskinstance.py:1206} INFO - Marking task as UP_FOR_RETRY. dag_id=submit_spark_job_v2, task_id=submit_spark_via_ssh, run_id=scheduled__2025-03-07T00:00:00+00:00, execution_date=20250307T000000, start_date=20250308T080333, end_date=20250308T080340
[2025-03-08T08:03:40.890+0000] {standard_task_runner.py:110} ERROR - Failed to execute job 33 for task submit_spark_via_ssh ([Errno None] Unable to connect to port 777 on 172.31.12.182; 10937)
[2025-03-08T08:03:40.925+0000] {local_task_job_runner.py:240} INFO - Task exited with return code 1
[2025-03-08T08:03:40.946+0000] {taskinstance.py:3498} INFO - 0 downstream tasks scheduled from follow-on schedule check
[2025-03-08T08:03:40.948+0000] {local_task_job_runner.py:222} INFO - ::endgroup::
[2025-03-08T09:26:11.852+0000] {local_task_job_runner.py:120} INFO - ::group::Pre task execution logs
[2025-03-08T09:26:11.875+0000] {taskinstance.py:2076} INFO - Dependencies all met for dep_context=non-requeueable deps ti=<TaskInstance: submit_spark_job_v2.submit_spark_via_ssh scheduled__2025-03-07T00:00:00+00:00 [queued]>
[2025-03-08T09:26:11.884+0000] {taskinstance.py:2076} INFO - Dependencies all met for dep_context=requeueable deps ti=<TaskInstance: submit_spark_job_v2.submit_spark_via_ssh scheduled__2025-03-07T00:00:00+00:00 [queued]>
[2025-03-08T09:26:11.884+0000] {taskinstance.py:2306} INFO - Starting attempt 2 of 2
[2025-03-08T09:26:11.897+0000] {taskinstance.py:2330} INFO - Executing <Task(SSHOperator): submit_spark_via_ssh> on 2025-03-07 00:00:00+00:00
[2025-03-08T09:26:11.903+0000] {standard_task_runner.py:63} INFO - Started process 589 to run task
[2025-03-08T09:26:11.906+0000] {standard_task_runner.py:90} INFO - Running: ['***', 'tasks', 'run', 'submit_spark_job_v2', 'submit_spark_via_ssh', 'scheduled__2025-03-07T00:00:00+00:00', '--job-id', '5', '--raw', '--subdir', 'DAGS_FOLDER/match_info_spark_process_v2.py', '--cfg-path', '/tmp/tmpkckppq8w']
[2025-03-08T09:26:11.908+0000] {standard_task_runner.py:91} INFO - Job 5: Subtask submit_spark_via_ssh
[2025-03-08T09:26:11.972+0000] {task_command.py:426} INFO - Running <TaskInstance: submit_spark_job_v2.submit_spark_via_ssh scheduled__2025-03-07T00:00:00+00:00 [running]> on host 40942f81e2c9
[2025-03-08T09:26:12.077+0000] {taskinstance.py:2648} INFO - Exporting env vars: AIRFLOW_CTX_DAG_OWNER='***' AIRFLOW_CTX_DAG_ID='submit_spark_job_v2' AIRFLOW_CTX_TASK_ID='submit_spark_via_ssh' AIRFLOW_CTX_EXECUTION_DATE='2025-03-07T00:00:00+00:00' AIRFLOW_CTX_TRY_NUMBER='2' AIRFLOW_CTX_DAG_RUN_ID='scheduled__2025-03-07T00:00:00+00:00'
[2025-03-08T09:26:12.078+0000] {taskinstance.py:430} INFO - ::endgroup::
[2025-03-08T09:26:12.093+0000] {ssh.py:151} INFO - Creating ssh_client
[2025-03-08T09:26:12.094+0000] {ssh.py:124} INFO - ssh_hook is not provided or invalid. Trying ssh_conn_id to create SSHHook.
[2025-03-08T09:26:12.111+0000] {base.py:84} INFO - Using connection ID 'spark_ssh_conn' for task execution.
[2025-03-08T09:26:12.112+0000] {ssh.py:301} WARNING - No Host Key Verification. This won't protect against Man-In-The-Middle attacks
[2025-03-08T09:26:12.115+0000] {transport.py:1909} INFO - Connected (version 2.0, client OpenSSH_9.6p1)
[2025-03-08T09:26:12.126+0000] {ssh.py:343} INFO - Failed to connect. Sleeping before retry attempt 1
[2025-03-08T09:26:15.974+0000] {transport.py:1909} INFO - Connected (version 2.0, client OpenSSH_9.6p1)
[2025-03-08T09:26:16.023+0000] {ssh.py:343} INFO - Failed to connect. Sleeping before retry attempt 2
[2025-03-08T09:26:19.818+0000] {transport.py:1909} INFO - Connected (version 2.0, client OpenSSH_9.6p1)
[2025-03-08T09:26:19.826+0000] {taskinstance.py:441} INFO - ::group::Post task execution logs
[2025-03-08T09:26:19.827+0000] {taskinstance.py:2905} ERROR - Task failed with exception
Traceback (most recent call last):
  File "/home/airflow/.local/lib/python3.9/site-packages/airflow/models/taskinstance.py", line 465, in _execute_task
    result = _execute_callable(context=context, **execute_callable_kwargs)
  File "/home/airflow/.local/lib/python3.9/site-packages/airflow/models/taskinstance.py", line 432, in _execute_callable
    return execute_callable(context=context, **execute_callable_kwargs)
  File "/home/airflow/.local/lib/python3.9/site-packages/airflow/models/baseoperator.py", line 400, in wrapper
    return func(self, *args, **kwargs)
  File "/home/airflow/.local/lib/python3.9/site-packages/airflow/providers/ssh/operators/ssh.py", line 190, in execute
    with self.get_ssh_client() as ssh_client:
  File "/home/airflow/.local/lib/python3.9/site-packages/airflow/providers/ssh/operators/ssh.py", line 152, in get_ssh_client
    return self.hook.get_conn()
  File "/home/airflow/.local/lib/python3.9/site-packages/airflow/providers/ssh/hooks/ssh.py", line 347, in get_conn
    for attempt in Retrying(
  File "/home/airflow/.local/lib/python3.9/site-packages/tenacity/__init__.py", line 347, in __iter__
    do = self.iter(retry_state=retry_state)
  File "/home/airflow/.local/lib/python3.9/site-packages/tenacity/__init__.py", line 325, in iter
    raise retry_exc.reraise()
  File "/home/airflow/.local/lib/python3.9/site-packages/tenacity/__init__.py", line 158, in reraise
    raise self.last_attempt.result()
  File "/usr/local/lib/python3.9/concurrent/futures/_base.py", line 439, in result
    return self.__get_result()
  File "/usr/local/lib/python3.9/concurrent/futures/_base.py", line 391, in __get_result
    raise self._exception
  File "/home/airflow/.local/lib/python3.9/site-packages/airflow/providers/ssh/hooks/ssh.py", line 354, in get_conn
    client.connect(**connect_kwargs)
  File "/home/airflow/.local/lib/python3.9/site-packages/paramiko/client.py", line 485, in connect
    self._auth(
  File "/home/airflow/.local/lib/python3.9/site-packages/paramiko/client.py", line 730, in _auth
    key = self._key_from_filepath(
  File "/home/airflow/.local/lib/python3.9/site-packages/paramiko/client.py", line 638, in _key_from_filepath
    key = klass.from_private_key_file(key_path, password)
  File "/home/airflow/.local/lib/python3.9/site-packages/paramiko/pkey.py", line 421, in from_private_key_file
    key = cls(filename=filename, password=password)
  File "/home/airflow/.local/lib/python3.9/site-packages/paramiko/rsakey.py", line 64, in __init__
    self._from_private_key_file(filename, password)
  File "/home/airflow/.local/lib/python3.9/site-packages/paramiko/rsakey.py", line 196, in _from_private_key_file
    data = self._read_private_key_file("RSA", filename, password)
  File "/home/airflow/.local/lib/python3.9/site-packages/paramiko/pkey.py", line 494, in _read_private_key_file
    with open(filename, "r") as f:
FileNotFoundError: [Errno 2] No such file or directory: '/home/ubuntu/airflow-setup/spark_connection/programmers-fc-key.pem'
[2025-03-08T09:26:19.842+0000] {taskinstance.py:1206} INFO - Marking task as FAILED. dag_id=submit_spark_job_v2, task_id=submit_spark_via_ssh, run_id=scheduled__2025-03-07T00:00:00+00:00, execution_date=20250307T000000, start_date=20250308T092611, end_date=20250308T092619
[2025-03-08T09:26:19.854+0000] {standard_task_runner.py:110} ERROR - Failed to execute job 5 for task submit_spark_via_ssh ([Errno 2] No such file or directory: '/home/ubuntu/airflow-setup/spark_connection/programmers-fc-key.pem'; 589)
[2025-03-08T09:26:19.879+0000] {local_task_job_runner.py:240} INFO - Task exited with return code 1
[2025-03-08T09:26:19.900+0000] {taskinstance.py:3498} INFO - 0 downstream tasks scheduled from follow-on schedule check
[2025-03-08T09:26:19.901+0000] {local_task_job_runner.py:222} INFO - ::endgroup::
