[2025-03-14T10:36:48.599+0000] {local_task_job_runner.py:120} INFO - ::group::Pre task execution logs
[2025-03-14T10:36:48.628+0000] {taskinstance.py:2076} INFO - Dependencies all met for dep_context=non-requeueable deps ti=<TaskInstance: daily_review_data_update.load_review_data_to_redshift scheduled__2025-03-13T03:50:00+00:00 [queued]>
[2025-03-14T10:36:48.642+0000] {taskinstance.py:2076} INFO - Dependencies all met for dep_context=requeueable deps ti=<TaskInstance: daily_review_data_update.load_review_data_to_redshift scheduled__2025-03-13T03:50:00+00:00 [queued]>
[2025-03-14T10:36:48.643+0000] {taskinstance.py:2306} INFO - Starting attempt 4 of 4
[2025-03-14T10:36:48.666+0000] {taskinstance.py:2330} INFO - Executing <Task(S3ToRedshiftOperator): load_review_data_to_redshift> on 2025-03-13 03:50:00+00:00
[2025-03-14T10:36:48.676+0000] {standard_task_runner.py:63} INFO - Started process 42420 to run task
[2025-03-14T10:36:48.682+0000] {standard_task_runner.py:90} INFO - Running: ['***', 'tasks', 'run', 'daily_review_data_update', 'load_review_data_to_redshift', 'scheduled__2025-03-13T03:50:00+00:00', '--job-id', '230', '--raw', '--subdir', 'DAGS_FOLDER/review_info_to_redshift.py', '--cfg-path', '/tmp/tmpex68o5sd']
[2025-03-14T10:36:48.684+0000] {standard_task_runner.py:91} INFO - Job 230: Subtask load_review_data_to_redshift
[2025-03-14T10:36:48.832+0000] {task_command.py:426} INFO - Running <TaskInstance: daily_review_data_update.load_review_data_to_redshift scheduled__2025-03-13T03:50:00+00:00 [running]> on host a0d797a25898
[2025-03-14T10:36:48.954+0000] {taskinstance.py:2648} INFO - Exporting env vars: AIRFLOW_CTX_DAG_OWNER='***' AIRFLOW_CTX_DAG_ID='daily_review_data_update' AIRFLOW_CTX_TASK_ID='load_review_data_to_redshift' AIRFLOW_CTX_EXECUTION_DATE='2025-03-13T03:50:00+00:00' AIRFLOW_CTX_TRY_NUMBER='4' AIRFLOW_CTX_DAG_RUN_ID='scheduled__2025-03-13T03:50:00+00:00'
[2025-03-14T10:36:48.955+0000] {taskinstance.py:430} INFO - ::endgroup::
[2025-03-14T10:36:48.985+0000] {base.py:84} INFO - Using connection ID 's3_conn_team' for task execution.
[2025-03-14T10:36:48.999+0000] {base.py:84} INFO - Using connection ID 's3_conn_team' for task execution.
[2025-03-14T10:36:49.000+0000] {connection_wrapper.py:384} INFO - AWS Connection (conn_id='s3_conn_team', conn_type='aws') credentials retrieved from login and password.
[2025-03-14T10:36:49.013+0000] {s3_to_redshift.py:193} INFO - Executing COPY command...
[2025-03-14T10:36:49.025+0000] {base.py:84} INFO - Using connection ID 'redshift_conn_team' for task execution.
[2025-03-14T10:36:49.436+0000] {sql.py:470} INFO - Running statement: BEGIN;, parameters: None
[2025-03-14T10:36:49.444+0000] {sql.py:470} INFO - Running statement: DELETE FROM analytics.player_review_info;, parameters: None
[2025-03-14T10:36:49.507+0000] {sql.py:479} INFO - Rows affected: 0
[2025-03-14T10:36:49.507+0000] {sql.py:470} INFO - Running statement: 
                    COPY analytics.player_review_info 
                    FROM 's3://de5-finalproj-team2/analytics/review_data_ML/2025-03-14/'
                    credentials
                    'aws_access_key_id=AKIA4RRVVY55RK5T7HCV;aws_secret_access_key=***'
                    
                    FORMAT AS PARQUET;
        , parameters: None
[2025-03-14T10:36:50.153+0000] {taskinstance.py:441} INFO - ::group::Post task execution logs
[2025-03-14T10:36:50.156+0000] {taskinstance.py:2905} ERROR - Task failed with exception
Traceback (most recent call last):
  File "/home/airflow/.local/lib/python3.9/site-packages/airflow/models/taskinstance.py", line 465, in _execute_task
    result = _execute_callable(context=context, **execute_callable_kwargs)
  File "/home/airflow/.local/lib/python3.9/site-packages/airflow/models/taskinstance.py", line 432, in _execute_callable
    return execute_callable(context=context, **execute_callable_kwargs)
  File "/home/airflow/.local/lib/python3.9/site-packages/airflow/models/baseoperator.py", line 400, in wrapper
    return func(self, *args, **kwargs)
  File "/home/airflow/.local/lib/python3.9/site-packages/airflow/providers/amazon/aws/transfers/s3_to_redshift.py", line 197, in execute
    redshift_hook.run(sql, autocommit=self.autocommit)
  File "/home/airflow/.local/lib/python3.9/site-packages/airflow/providers/common/sql/hooks/sql.py", line 418, in run
    self._run_command(cur, sql_statement, parameters)
  File "/home/airflow/.local/lib/python3.9/site-packages/airflow/providers/common/sql/hooks/sql.py", line 475, in _run_command
    cur.execute(sql_statement)
  File "/home/airflow/.local/lib/python3.9/site-packages/redshift_connector/cursor.py", line 248, in execute
    raise e
  File "/home/airflow/.local/lib/python3.9/site-packages/redshift_connector/cursor.py", line 241, in execute
    self._c.execute(self, operation, args)
  File "/home/airflow/.local/lib/python3.9/site-packages/redshift_connector/core.py", line 1987, in execute
    self.handle_messages(cursor)
  File "/home/airflow/.local/lib/python3.9/site-packages/redshift_connector/core.py", line 2194, in handle_messages
    raise self.error
redshift_connector.error.ProgrammingError: {'S': 'ERROR', 'C': 'XX000', 'M': 'Spectrum Scan Error', 'D': "\n  -----------------------------------------------\n  error:  Spectrum Scan Error\n  code:      15007\n  context:   File 'https://s3.ap-northeast-2.amazonaws.com/de5-finalproj-team2/analytics/review_data_ML/2025-03-14/part-00000-a6eaf0d7-3fc3-499f-9b31-7ef942a8c04a-c000.snappy.parquet' has an incompatible Parquet schema for column 's3://de5-finalproj-team2/analytics/rev\n  query:     3439005\n  location:  dory_util.cpp:1758\n  process:   worker_thread [pid=32172]\n  -----------------------------------------------\n", 'F': '/opt/brazil-pkg-cache/packages/RedshiftPADB/RedshiftPADB-1.0.8470.0/AL2_x86_64/generic-flavor/src/src/sys/xen_execute.cpp', 'L': '13540', 'R': 'pg_throw'}
[2025-03-14T10:36:50.175+0000] {taskinstance.py:1206} INFO - Marking task as FAILED. dag_id=daily_review_data_update, task_id=load_review_data_to_redshift, run_id=scheduled__2025-03-13T03:50:00+00:00, execution_date=20250313T035000, start_date=20250314T103648, end_date=20250314T103650
[2025-03-14T10:36:50.192+0000] {standard_task_runner.py:110} ERROR - Failed to execute job 230 for task load_review_data_to_redshift ({'S': 'ERROR', 'C': 'XX000', 'M': 'Spectrum Scan Error', 'D': "\n  -----------------------------------------------\n  error:  Spectrum Scan Error\n  code:      15007\n  context:   File 'https://s3.ap-northeast-2.amazonaws.com/de5-finalproj-team2/analytics/review_data_ML/2025-03-14/part-00000-a6eaf0d7-3fc3-499f-9b31-7ef942a8c04a-c000.snappy.parquet' has an incompatible Parquet schema for column 's3://de5-finalproj-team2/analytics/rev\n  query:     3439005\n  location:  dory_util.cpp:1758\n  process:   worker_thread [pid=32172]\n  -----------------------------------------------\n", 'F': '/opt/brazil-pkg-cache/packages/RedshiftPADB/RedshiftPADB-1.0.8470.0/AL2_x86_64/generic-flavor/src/src/sys/xen_execute.cpp', 'L': '13540', 'R': 'pg_throw'}; 42420)
[2025-03-14T10:36:50.226+0000] {local_task_job_runner.py:240} INFO - Task exited with return code 1
[2025-03-14T10:36:50.255+0000] {taskinstance.py:3498} INFO - 0 downstream tasks scheduled from follow-on schedule check
[2025-03-14T10:36:50.257+0000] {local_task_job_runner.py:222} INFO - ::endgroup::
