[2025-03-14T10:18:07.396+0000] {local_task_job_runner.py:120} INFO - ::group::Pre task execution logs
[2025-03-14T10:18:07.444+0000] {taskinstance.py:2076} INFO - Dependencies all met for dep_context=non-requeueable deps ti=<TaskInstance: daily_review_data_update.load_review_data_to_redshift scheduled__2025-03-13T03:50:00+00:00 [queued]>
[2025-03-14T10:18:07.469+0000] {taskinstance.py:2076} INFO - Dependencies all met for dep_context=requeueable deps ti=<TaskInstance: daily_review_data_update.load_review_data_to_redshift scheduled__2025-03-13T03:50:00+00:00 [queued]>
[2025-03-14T10:18:07.470+0000] {taskinstance.py:2306} INFO - Starting attempt 1 of 2
[2025-03-14T10:18:07.523+0000] {taskinstance.py:2330} INFO - Executing <Task(S3ToRedshiftOperator): load_review_data_to_redshift> on 2025-03-13 03:50:00+00:00
[2025-03-14T10:18:07.544+0000] {standard_task_runner.py:63} INFO - Started process 40716 to run task
[2025-03-14T10:18:07.551+0000] {standard_task_runner.py:90} INFO - Running: ['***', 'tasks', 'run', 'daily_review_data_update', 'load_review_data_to_redshift', 'scheduled__2025-03-13T03:50:00+00:00', '--job-id', '226', '--raw', '--subdir', 'DAGS_FOLDER/review_info_to_redshift.py', '--cfg-path', '/tmp/tmpg1_dakx6']
[2025-03-14T10:18:07.559+0000] {standard_task_runner.py:91} INFO - Job 226: Subtask load_review_data_to_redshift
[2025-03-14T10:18:07.649+0000] {task_command.py:426} INFO - Running <TaskInstance: daily_review_data_update.load_review_data_to_redshift scheduled__2025-03-13T03:50:00+00:00 [running]> on host a0d797a25898
[2025-03-14T10:18:07.824+0000] {taskinstance.py:2648} INFO - Exporting env vars: AIRFLOW_CTX_DAG_OWNER='***' AIRFLOW_CTX_DAG_ID='daily_review_data_update' AIRFLOW_CTX_TASK_ID='load_review_data_to_redshift' AIRFLOW_CTX_EXECUTION_DATE='2025-03-13T03:50:00+00:00' AIRFLOW_CTX_TRY_NUMBER='1' AIRFLOW_CTX_DAG_RUN_ID='scheduled__2025-03-13T03:50:00+00:00'
[2025-03-14T10:18:07.825+0000] {taskinstance.py:430} INFO - ::endgroup::
[2025-03-14T10:18:07.861+0000] {base.py:84} INFO - Using connection ID 's3_conn_team' for task execution.
[2025-03-14T10:18:07.874+0000] {base.py:84} INFO - Using connection ID 's3_conn_team' for task execution.
[2025-03-14T10:18:07.875+0000] {connection_wrapper.py:384} INFO - AWS Connection (conn_id='s3_conn_team', conn_type='aws') credentials retrieved from login and password.
[2025-03-14T10:18:07.890+0000] {s3_to_redshift.py:193} INFO - Executing COPY command...
[2025-03-14T10:18:07.903+0000] {base.py:84} INFO - Using connection ID 'redshift_conn_team' for task execution.
[2025-03-14T10:18:08.333+0000] {sql.py:470} INFO - Running statement: BEGIN;, parameters: None
[2025-03-14T10:18:08.343+0000] {sql.py:470} INFO - Running statement: DELETE FROM analytics.player_review_info;, parameters: None
[2025-03-14T10:18:08.393+0000] {sql.py:479} INFO - Rows affected: 0
[2025-03-14T10:18:08.395+0000] {sql.py:470} INFO - Running statement: 
                    COPY analytics.player_review_info 
                    FROM 's3://de5-finalproj-team2/analytics/review_data_ML/2025-03-14/'
                    credentials
                    'aws_access_key_id=AKIA4RRVVY55RK5T7HCV;aws_secret_access_key=***'
                    
                    FORMAT AS PARQUET;
        , parameters: None
[2025-03-14T10:18:26.977+0000] {taskinstance.py:441} INFO - ::group::Post task execution logs
[2025-03-14T10:18:26.978+0000] {taskinstance.py:2905} ERROR - Task failed with exception
Traceback (most recent call last):
  File "/home/airflow/.local/lib/python3.9/site-packages/airflow/models/taskinstance.py", line 465, in _execute_task
    result = _execute_callable(context=context, **execute_callable_kwargs)
  File "/home/airflow/.local/lib/python3.9/site-packages/airflow/models/taskinstance.py", line 432, in _execute_callable
    return execute_callable(context=context, **execute_callable_kwargs)
  File "/home/airflow/.local/lib/python3.9/site-packages/airflow/models/baseoperator.py", line 400, in wrapper
    return func(self, *args, **kwargs)
  File "/home/airflow/.local/lib/python3.9/site-packages/airflow/providers/amazon/aws/transfers/s3_to_redshift.py", line 197, in execute
    redshift_hook.run(sql, autocommit=self.autocommit)
  File "/home/airflow/.local/lib/python3.9/site-packages/airflow/providers/common/sql/hooks/sql.py", line 418, in run
    self._run_command(cur, sql_statement, parameters)
  File "/home/airflow/.local/lib/python3.9/site-packages/airflow/providers/common/sql/hooks/sql.py", line 475, in _run_command
    cur.execute(sql_statement)
  File "/home/airflow/.local/lib/python3.9/site-packages/redshift_connector/cursor.py", line 248, in execute
    raise e
  File "/home/airflow/.local/lib/python3.9/site-packages/redshift_connector/cursor.py", line 241, in execute
    self._c.execute(self, operation, args)
  File "/home/airflow/.local/lib/python3.9/site-packages/redshift_connector/core.py", line 1987, in execute
    self.handle_messages(cursor)
  File "/home/airflow/.local/lib/python3.9/site-packages/redshift_connector/core.py", line 2194, in handle_messages
    raise self.error
redshift_connector.error.ProgrammingError: {'S': 'ERROR', 'C': 'XX000', 'M': 'Spectrum Scan Error', 'D': "\n  -----------------------------------------------\n  error:  Spectrum Scan Error\n  code:      15007\n  context:   File 'https://s3.ap-northeast-2.amazonaws.com/de5-finalproj-team2/analytics/review_data_ML/2025-03-14/part-00000-82d2888f-ff46-4fdd-a351-3bca3fc09726-c000.snappy.parquet' has an incompatible Parquet schema for column 's3://de5-finalproj-team2/analytics/rev\n  query:     3438639\n  location:  dory_util.cpp:1758\n  process:   worker_thread [pid=12980]\n  -----------------------------------------------\n", 'F': '/opt/brazil-pkg-cache/packages/RedshiftPADB/RedshiftPADB-1.0.8470.0/AL2_x86_64/generic-flavor/src/src/sys/xen_execute.cpp', 'L': '13540', 'R': 'pg_throw'}
[2025-03-14T10:18:27.008+0000] {taskinstance.py:1206} INFO - Marking task as UP_FOR_RETRY. dag_id=daily_review_data_update, task_id=load_review_data_to_redshift, run_id=scheduled__2025-03-13T03:50:00+00:00, execution_date=20250313T035000, start_date=20250314T101807, end_date=20250314T101827
[2025-03-14T10:18:27.034+0000] {standard_task_runner.py:110} ERROR - Failed to execute job 226 for task load_review_data_to_redshift ({'S': 'ERROR', 'C': 'XX000', 'M': 'Spectrum Scan Error', 'D': "\n  -----------------------------------------------\n  error:  Spectrum Scan Error\n  code:      15007\n  context:   File 'https://s3.ap-northeast-2.amazonaws.com/de5-finalproj-team2/analytics/review_data_ML/2025-03-14/part-00000-82d2888f-ff46-4fdd-a351-3bca3fc09726-c000.snappy.parquet' has an incompatible Parquet schema for column 's3://de5-finalproj-team2/analytics/rev\n  query:     3438639\n  location:  dory_util.cpp:1758\n  process:   worker_thread [pid=12980]\n  -----------------------------------------------\n", 'F': '/opt/brazil-pkg-cache/packages/RedshiftPADB/RedshiftPADB-1.0.8470.0/AL2_x86_64/generic-flavor/src/src/sys/xen_execute.cpp', 'L': '13540', 'R': 'pg_throw'}; 40716)
[2025-03-14T10:18:27.075+0000] {local_task_job_runner.py:240} INFO - Task exited with return code 1
[2025-03-14T10:18:27.110+0000] {taskinstance.py:3498} INFO - 0 downstream tasks scheduled from follow-on schedule check
[2025-03-14T10:18:27.113+0000] {local_task_job_runner.py:222} INFO - ::endgroup::
