[2025-03-08T06:11:28.200+0000] {local_task_job_runner.py:120} INFO - ::group::Pre task execution logs
[2025-03-08T06:11:28.223+0000] {taskinstance.py:2076} INFO - Dependencies all met for dep_context=non-requeueable deps ti=<TaskInstance: parquet_to_redshift.s3_to_redshift_match_trend_data manual__2025-03-08T06:05:02.968887+00:00 [queued]>
[2025-03-08T06:11:28.233+0000] {taskinstance.py:2076} INFO - Dependencies all met for dep_context=requeueable deps ti=<TaskInstance: parquet_to_redshift.s3_to_redshift_match_trend_data manual__2025-03-08T06:05:02.968887+00:00 [queued]>
[2025-03-08T06:11:28.233+0000] {taskinstance.py:2306} INFO - Starting attempt 2 of 2
[2025-03-08T06:11:28.247+0000] {taskinstance.py:2330} INFO - Executing <Task(S3ToRedshiftOperator): s3_to_redshift_match_trend_data> on 2025-03-08 06:05:02.968887+00:00
[2025-03-08T06:11:28.254+0000] {standard_task_runner.py:63} INFO - Started process 7316 to run task
[2025-03-08T06:11:28.258+0000] {standard_task_runner.py:90} INFO - Running: ['***', 'tasks', 'run', 'parquet_to_redshift', 's3_to_redshift_match_trend_data', 'manual__2025-03-08T06:05:02.968887+00:00', '--job-id', '12', '--raw', '--subdir', 'DAGS_FOLDER/match_info_redshift.py', '--cfg-path', '/tmp/tmp3x6kybjz']
[2025-03-08T06:11:28.260+0000] {standard_task_runner.py:91} INFO - Job 12: Subtask s3_to_redshift_match_trend_data
[2025-03-08T06:11:28.327+0000] {task_command.py:426} INFO - Running <TaskInstance: parquet_to_redshift.s3_to_redshift_match_trend_data manual__2025-03-08T06:05:02.968887+00:00 [running]> on host be828dc9717c
[2025-03-08T06:11:28.397+0000] {logging_mixin.py:188} WARNING - /home/***/.local/lib/python3.9/site-packages/***/utils/context.py:212 AirflowContextDeprecationWarning: Accessing 'execution_date' from the template is deprecated and will be removed in a future version. Please use 'data_interval_start' or 'logical_date' instead.
[2025-03-08T06:11:28.442+0000] {taskinstance.py:2648} INFO - Exporting env vars: AIRFLOW_CTX_DAG_OWNER='***' AIRFLOW_CTX_DAG_ID='parquet_to_redshift' AIRFLOW_CTX_TASK_ID='s3_to_redshift_match_trend_data' AIRFLOW_CTX_EXECUTION_DATE='2025-03-08T06:05:02.968887+00:00' AIRFLOW_CTX_TRY_NUMBER='2' AIRFLOW_CTX_DAG_RUN_ID='manual__2025-03-08T06:05:02.968887+00:00'
[2025-03-08T06:11:28.443+0000] {taskinstance.py:430} INFO - ::endgroup::
[2025-03-08T06:11:28.475+0000] {base.py:84} INFO - Using connection ID 's3_conn_team' for task execution.
[2025-03-08T06:11:28.488+0000] {base.py:84} INFO - Using connection ID 's3_conn_team' for task execution.
[2025-03-08T06:11:28.489+0000] {connection_wrapper.py:384} INFO - AWS Connection (conn_id='s3_conn_team', conn_type='aws') credentials retrieved from login and password.
[2025-03-08T06:11:28.501+0000] {s3_to_redshift.py:193} INFO - Executing COPY command...
[2025-03-08T06:11:28.513+0000] {base.py:84} INFO - Using connection ID 'redshift_conn_team' for task execution.
[2025-03-08T06:11:28.907+0000] {sql.py:470} INFO - Running statement: 
                    COPY trend_analytics.match_info 
                    FROM 's3://de5-finalproj-team2/trend_analysis/match_data/2025-03-08/'
                    credentials
                    'aws_access_key_id=AKIA4RRVVY55RK5T7HCV;aws_secret_access_key=***'
                    
                    FORMAT AS PARQUET;
        , parameters: None
[2025-03-08T06:11:28.924+0000] {taskinstance.py:441} INFO - ::group::Post task execution logs
[2025-03-08T06:11:28.925+0000] {taskinstance.py:2905} ERROR - Task failed with exception
Traceback (most recent call last):
  File "/home/airflow/.local/lib/python3.9/site-packages/airflow/models/taskinstance.py", line 465, in _execute_task
    result = _execute_callable(context=context, **execute_callable_kwargs)
  File "/home/airflow/.local/lib/python3.9/site-packages/airflow/models/taskinstance.py", line 432, in _execute_callable
    return execute_callable(context=context, **execute_callable_kwargs)
  File "/home/airflow/.local/lib/python3.9/site-packages/airflow/models/baseoperator.py", line 400, in wrapper
    return func(self, *args, **kwargs)
  File "/home/airflow/.local/lib/python3.9/site-packages/airflow/providers/amazon/aws/transfers/s3_to_redshift.py", line 197, in execute
    redshift_hook.run(sql, autocommit=self.autocommit)
  File "/home/airflow/.local/lib/python3.9/site-packages/airflow/providers/common/sql/hooks/sql.py", line 418, in run
    self._run_command(cur, sql_statement, parameters)
  File "/home/airflow/.local/lib/python3.9/site-packages/airflow/providers/common/sql/hooks/sql.py", line 475, in _run_command
    cur.execute(sql_statement)
  File "/home/airflow/.local/lib/python3.9/site-packages/redshift_connector/cursor.py", line 248, in execute
    raise e
  File "/home/airflow/.local/lib/python3.9/site-packages/redshift_connector/cursor.py", line 241, in execute
    self._c.execute(self, operation, args)
  File "/home/airflow/.local/lib/python3.9/site-packages/redshift_connector/core.py", line 1987, in execute
    self.handle_messages(cursor)
  File "/home/airflow/.local/lib/python3.9/site-packages/redshift_connector/core.py", line 2194, in handle_messages
    raise self.error
redshift_connector.error.ProgrammingError: {'S': 'ERROR', 'C': 'XX000', 'M': 'Cannot COPY into nonexistent table match_info', 'F': '/opt/brazil-pkg-cache/packages/RedshiftPADB/RedshiftPADB-1.0.8470.0/AL2_x86_64/generic-flavor/src/src/sys/compression_analyzer.cpp', 'L': '710', 'R': 'XenGetLoadTableId'}
[2025-03-08T06:11:28.940+0000] {taskinstance.py:1206} INFO - Marking task as FAILED. dag_id=parquet_to_redshift, task_id=s3_to_redshift_match_trend_data, run_id=manual__2025-03-08T06:05:02.968887+00:00, execution_date=20250308T060502, start_date=20250308T061128, end_date=20250308T061128
[2025-03-08T06:11:28.954+0000] {standard_task_runner.py:110} ERROR - Failed to execute job 12 for task s3_to_redshift_match_trend_data ({'S': 'ERROR', 'C': 'XX000', 'M': 'Cannot COPY into nonexistent table match_info', 'F': '/opt/brazil-pkg-cache/packages/RedshiftPADB/RedshiftPADB-1.0.8470.0/AL2_x86_64/generic-flavor/src/src/sys/compression_analyzer.cpp', 'L': '710', 'R': 'XenGetLoadTableId'}; 7316)
[2025-03-08T06:11:28.993+0000] {local_task_job_runner.py:240} INFO - Task exited with return code 1
[2025-03-08T06:11:29.019+0000] {taskinstance.py:3498} INFO - 0 downstream tasks scheduled from follow-on schedule check
[2025-03-08T06:11:29.021+0000] {local_task_job_runner.py:222} INFO - ::endgroup::
